Workbook
Name DT_AVGCharge: #REF!
Name DT_AVGSalary: #REF!
Name DT_ClientName: #REF!
Name DT_Ex_Curr_Rate: #REF!
Name DT_WorkDaysPA: #REF!
Name Possibility: #REF!

Sheet Summary
B2: Summary People Stats
R4: Leavers | S4: =DATE(YEAR(S$5), MONTH(S$5), 1) -> 45444 | T4: =DATE(YEAR(T$5), MONTH(T$5), 1) -> 45474 | U4: =DATE(YEAR(U$5), MONTH(U$5), 1) -> 45505 | V4: =DATE(YEAR(V$5), MONTH(V$5), 1) -> 45536 | W4: =DATE(YEAR(W$5), MONTH(W$5), 1) -> 45566 | X4: =DATE(YEAR(X$5), MONTH(X$5), 1) -> 45597 | Y4: =DATE(YEAR(Y$5), MONTH(Y$5), 1) -> 45627 | Z4: =DATE(YEAR(Z$5), MONTH(Z$5), 1) -> 45658 | ... BI4: =DATE(YEAR(BI$5), MONTH(BI$5), 1) -> 1
B5: Summary by business unit - Previous Month End | H5: Summary by business unit - LIVE | R5: Business Unit | S5: 30/06/2024 | T5: 31/07/2024 | U5: 31/08/2024 | V5: 30/09/2024 | W5: 31/10/2024 | X5: 30/11/2024 | Y5: 31/12/2024 | Z5: 30/01/2025 | AA5: 28/02/2025 | AB5: 31/03/2025 | AC5: 30/04/2025 | AD5: 31/05/2025 | AE5: 30/06/2025 | AF5: 31/07/2025 | AG5: 31/08/2025 | AH5: 30/09/2025 | AI5: 31/10/2025 | AJ5: 30/11/2025 | AK5: 31/12/2025 | AL5: 30/01/2026 | AM5: 28/02/2026 | AN5: 31/03/2026 | AO5: 30/04/2026 | AP5: 31/05/2026 | AQ5: 30/06/2026 | AR5: 31/07/2026 | AS5: 31/08/2026 | AT5: 30/09/2026 | AU5: 31/10/2026 | AV5: 30/11/2026 | AW5: 31/12/2026 | AX5: 30/01/2027 | AY5: 28/02/2027 | AZ5: 31/03/2027 | BA5: 30/04/2027 | BB5: 31/05/2027 | BC5: 30/06/2027 | BD5: 31/07/2027 | BE5: 31/08/2027 | BF5: 30/09/2027 | BG5: 31/10/2027
R6: Engineering | S6: 1 | T6: 0 | U6: 0 | V6: 0 | W6: 3 | Y6: 1 | AA6: 1 | AC6: 1 | AE6: 1 | AF6: =SUMIFS('Regional allocations LIVE'!$T:$T, 'Regional allocations LIVE'!$H:$H, $R6, 'Regional allocations LIVE'!$R:$R, ">=" & AF$4, 'Regional allocations LIVE'!$R:$R, "<=" & Table14[[#Headers],[31/07/2025]] ) -> 1 | AG6: =SUMIFS('Regional allocations LIVE'!$T:$T, 'Regional allocations LIVE'!$H:$H, $R6, 'Regional allocations LIVE'!$R:$R, ">=" & AG$4, 'Regional allocations LIVE'!$R:$R, "<=" & Table14[[#Headers],[31/08/2025]] ) -> 1 | AH6: =SUMIFS('Regional allocations LIVE'!$T:$T, 'Regional allocations LIVE'!$H:$H, $R6, 'Regional allocations LIVE'!$R:$R, ">=" & AH$4, 'Regional allocations LIVE'!$R:$R, "<=" & Table14[[#Headers],[30/09/2025]] ) -> 1.8 | AI6: =SUMIFS('Regional allocations LIVE'!$T:$T, 'Regional allocations LIVE'!$H:$H, $R6, 'Regional allocations LIVE'!$R:$R, ">=" & AI$4, 'Regional allocations LIVE'!$R:$R, "<=" & Table14[[#Headers],[31/10/2025]] ) -> 0 | AJ6: =SUMIFS('Regional allocations LIVE'!$T:$T, 'Regional allocations LIVE'!$H:$H, $R6, 'Regional allocations LIVE'!$R:$R, ">=" & AJ$4, 'Regional allocations LIVE'!$R:$R, "<=" & Table14[[#Headers],[30/11/2025]] ) -> 0 | AK6: =SUMIFS('Regional allocations LIVE'!$T:$T, 'Regional allocations LIVE'!$H:$H, $R6, 'Regional allocations LIVE'!$R:$R, ">=" & AK$4, 'Regional allocations LIVE'!$R:$R, "<=" & Table14[[#Headers],[31/12/2025]] ) -> 0 | AL6: =SUMIFS('Regional allocations LIVE'!$T:$T, 'Regional allocations LIVE'!$H:$H, $R6, 'Regional allocations LIVE'!$R:$R, ">=" & AL$4, 'Regional allocations LIVE'!$R:$R, "<=" & Table14[[#Headers],[30/01/2026]] ) -> 0 | AM6: =SUMIFS('Regional allocations LIVE'!$T:$T, 'Regional allocations LIVE'!$H:$H, $R6, 'Regional allocations LIVE'!$R:$R, ">=" & AM$4, 'Regional allocations LIVE'!$R:$R, "<=" & Table14[[#Headers],[28/02/2026]] ) -> 0 | AN6: =SUMIFS('Regional allocations LIVE'!$T:$T, 'Regional allocations LIVE'!$H:$H, $R6, 'Regional allocations LIVE'!$R:$R, ">=" & AN$4, 'Regional allocations LIVE'!$R:$R, "<=" & Table14[[#Headers],[31/03/2026]] ) -> 0 | AO6: =SUMIFS('Regional allocations LIVE'!$T:$T, 'Regional allocations LIVE'!$H:$H, $R6, 'Regional allocations LIVE'!$R:$R, ">=" & AO$4, 'Regional allocations LIVE'!$R:$R, "<=" & Table14[[#Headers],[30/04/2026]] ) -> 0 | AP6: =SUMIFS('Regional allocations LIVE'!$T:$T, 'Regional allocations LIVE'!$H:$H, $R6, 'Regional allocations LIVE'!$R:$R, ">=" & AP$4, 'Regional allocations LIVE'!$R:$R, "<=" & Table14[[#Headers],[31/05/2026]] ) -> 0 | AQ6: =SUMIFS('Regional allocations LIVE'!$T:$T, 'Regional allocations LIVE'!$H:$H, $R6, 'Regional allocations LIVE'!$R:$R, ">=" & AQ$4, 'Regional allocations LIVE'!$R:$R, "<=" & Table14[[#Headers],[30/06/2026]] ) -> 0 | AR6: =SUMIFS('Regional allocations LIVE'!$T:$T, 'Regional allocations LIVE'!$H:$H, $R6, 'Regional allocations LIVE'!$R:$R, ">=" & AR$4, 'Regional allocations LIVE'!$R:$R, "<=" & Table14[[#Headers],[31/07/2026]] ) -> 0 | AS6: =SUMIFS('Regional allocations LIVE'!$T:$T, 'Regional allocations LIVE'!$H:$H, $R6, 'Regional allocations LIVE'!$R:$R, ">=" & AS$4, 'Regional allocations LIVE'!$R:$R, "<=" & Table14[[#Headers],[31/08/2026]] ) -> 0 | AT6: =SUMIFS('Regional allocations LIVE'!$T:$T, 'Regional allocations LIVE'!$H:$H, $R6, 'Regional allocations LIVE'!$R:$R, ">=" & AT$4, 'Regional allocations LIVE'!$R:$R, "<=" & Table14[[#Headers],[30/09/2026]] ) -> 0 | AU6: =SUMIFS('Regional allocations LIVE'!$T:$T, 'Regional allocations LIVE'!$H:$H, $R6, 'Regional allocations LIVE'!$R:$R, ">=" & AU$4, 'Regional allocations LIVE'!$R:$R, "<=" & Table14[[#Headers],[31/10/2026]] ) -> 0 | AV6: =SUMIFS('Regional allocations LIVE'!$T:$T, 'Regional allocations LIVE'!$H:$H, $R6, 'Regional allocations LIVE'!$R:$R, ">=" & AV$4, 'Regional allocations LIVE'!$R:$R, "<=" & Table14[[#Headers],[30/11/2026]] ) -> 0 | AW6: =SUMIFS('Regional allocations LIVE'!$T:$T, 'Regional allocations LIVE'!$H:$H, $R6, 'Regional allocations LIVE'!$R:$R, ">=" & AW$4, 'Regional allocations LIVE'!$R:$R, "<=" & Table14[[#Headers],[31/12/2026]] ) -> 0 | AX6: =SUMIFS('Regional allocations LIVE'!$T:$T, 'Regional allocations LIVE'!$H:$H, $R6, 'Regional allocations LIVE'!$R:$R, ">=" & AX$4, 'Regional allocations LIVE'!$R:$R, "<=" & Table14[[#Headers],[30/01/2027]] ) -> 0 | AY6: =SUMIFS('Regional allocations LIVE'!$T:$T, 'Regional allocations LIVE'!$H:$H, $R6, 'Regional allocations LIVE'!$R:$R, ">=" & AY$4, 'Regional allocations LIVE'!$R:$R, "<=" & Table14[[#Headers],[28/02/2027]] ) -> 0 | AZ6: =SUMIFS('Regional allocations LIVE'!$T:$T, 'Regional allocations LIVE'!$H:$H, $R6, 'Regional allocations LIVE'!$R:$R, ">=" & AZ$4, 'Regional allocations LIVE'!$R:$R, "<=" & Table14[[#Headers],[31/03/2027]] ) -> 0 | BA6: =SUMIFS('Regional allocations LIVE'!$T:$T, 'Regional allocations LIVE'!$H:$H, $R6, 'Regional allocations LIVE'!$R:$R, ">=" & BA$4, 'Regional allocations LIVE'!$R:$R, "<=" & Table14[[#Headers],[30/04/2027]] ) -> 0 | BB6: =SUMIFS('Regional allocations LIVE'!$T:$T, 'Regional allocations LIVE'!$H:$H, $R6, 'Regional allocations LIVE'!$R:$R, ">=" & BB$4, 'Regional allocations LIVE'!$R:$R, "<=" & Table14[[#Headers],[31/05/2027]] ) -> 0 | BC6: =SUMIFS('Regional allocations LIVE'!$T:$T, 'Regional allocations LIVE'!$H:$H, $R6, 'Regional allocations LIVE'!$R:$R, ">=" & BC$4, 'Regional allocations LIVE'!$R:$R, "<=" & Table14[[#Headers],[30/06/2027]] ) -> 0 | BD6: =SUMIFS('Regional allocations LIVE'!$T:$T, 'Regional allocations LIVE'!$H:$H, $R6, 'Regional allocations LIVE'!$R:$R, ">=" & BD$4, 'Regional allocations LIVE'!$R:$R, "<=" & Table14[[#Headers],[31/07/2027]] ) -> 0 | BE6: =SUMIFS('Regional allocations LIVE'!$T:$T, 'Regional allocations LIVE'!$H:$H, $R6, 'Regional allocations LIVE'!$R:$R, ">=" & BE$4, 'Regional allocations LIVE'!$R:$R, "<=" & Table14[[#Headers],[31/08/2027]] ) -> 0 | BF6: =SUMIFS('Regional allocations LIVE'!$T:$T, 'Regional allocations LIVE'!$H:$H, $R6, 'Regional allocations LIVE'!$R:$R, ">=" & BF$4, 'Regional allocations LIVE'!$R:$R, "<=" & Table14[[#Headers],[30/09/2027]] ) -> 0 | BG6: =SUMIFS('Regional allocations LIVE'!$T:$T, 'Regional allocations LIVE'!$H:$H, $R6, 'Regional allocations LIVE'!$R:$R, ">=" & BG$4, 'Regional allocations LIVE'!$R:$R, "<=" & Table14[[#Headers],[31/10/2027]] ) -> 0
B7: Business Unit | C7: Headcount | E7: Regional Headcount | H7: Business Unit | I7: Headcount | J7: Vaccancies to backfill | K7: Vaccancies for new roles | L7: Increase headcount roles TBC | M7: Contractors | N7: Perm Headcount (minus contractors) | O7: Perm with Vaccancies filled | R7: Sales | S7: 0 | T7: 0 | U7: 0 | V7: 1 | W7: 0 | AF7: =SUMIFS('Regional allocations LIVE'!$T:$T, 'Regional allocations LIVE'!$H:$H, $R7, 'Regional allocations LIVE'!$R:$R, ">=" & AF$4, 'Regional allocations LIVE'!$R:$R, "<=" & Table14[[#Headers],[31/07/2025]] ) -> 0 | AG7: =SUMIFS('Regional allocations LIVE'!$T:$T, 'Regional allocations LIVE'!$H:$H, $R7, 'Regional allocations LIVE'!$R:$R, ">=" & AG$4, 'Regional allocations LIVE'!$R:$R, "<=" & Table14[[#Headers],[31/08/2025]] ) -> 0 | AH7: =SUMIFS('Regional allocations LIVE'!$T:$T, 'Regional allocations LIVE'!$H:$H, $R7, 'Regional allocations LIVE'!$R:$R, ">=" & AH$4, 'Regional allocations LIVE'!$R:$R, "<=" & Table14[[#Headers],[30/09/2025]] ) -> 0 | AI7: =SUMIFS('Regional allocations LIVE'!$T:$T, 'Regional allocations LIVE'!$H:$H, $R7, 'Regional allocations LIVE'!$R:$R, ">=" & AI$4, 'Regional allocations LIVE'!$R:$R, "<=" & Table14[[#Headers],[31/10/2025]] ) -> 0 | AJ7: =SUMIFS('Regional allocations LIVE'!$T:$T, 'Regional allocations LIVE'!$H:$H, $R7, 'Regional allocations LIVE'!$R:$R, ">=" & AJ$4, 'Regional allocations LIVE'!$R:$R, "<=" & Table14[[#Headers],[30/11/2025]] ) -> 0 | AK7: =SUMIFS('Regional allocations LIVE'!$T:$T, 'Regional allocations LIVE'!$H:$H, $R7, 'Regional allocations LIVE'!$R:$R, ">=" & AK$4, 'Regional allocations LIVE'!$R:$R, "<=" & Table14[[#Headers],[31/12/2025]] ) -> 0 | AL7: =SUMIFS('Regional allocations LIVE'!$T:$T, 'Regional allocations LIVE'!$H:$H, $R7, 'Regional allocations LIVE'!$R:$R, ">=" & AL$4, 'Regional allocations LIVE'!$R:$R, "<=" & Table14[[#Headers],[30/01/2026]] ) -> 0 | AM7: =SUMIFS('Regional allocations LIVE'!$T:$T, 'Regional allocations LIVE'!$H:$H, $R7, 'Regional allocations LIVE'!$R:$R, ">=" & AM$4, 'Regional allocations LIVE'!$R:$R, "<=" & Table14[[#Headers],[28/02/2026]] ) -> 0 | AN7: =SUMIFS('Regional allocations LIVE'!$T:$T, 'Regional allocations LIVE'!$H:$H, $R7, 'Regional allocations LIVE'!$R:$R, ">=" & AN$4, 'Regional allocations LIVE'!$R:$R, "<=" & Table14[[#Headers],[31/03/2026]] ) -> 0 | AO7: =SUMIFS('Regional allocations LIVE'!$T:$T, 'Regional allocations LIVE'!$H:$H, $R7, 'Regional allocations LIVE'!$R:$R, ">=" & AO$4, 'Regional allocations LIVE'!$R:$R, "<=" & Table14[[#Headers],[30/04/2026]] ) -> 0 | AP7: =SUMIFS('Regional allocations LIVE'!$T:$T, 'Regional allocations LIVE'!$H:$H, $R7, 'Regional allocations LIVE'!$R:$R, ">=" & AP$4, 'Regional allocations LIVE'!$R:$R, "<=" & Table14[[#Headers],[31/05/2026]] ) -> 0 | AQ7: =SUMIFS('Regional allocations LIVE'!$T:$T, 'Regional allocations LIVE'!$H:$H, $R7, 'Regional allocations LIVE'!$R:$R, ">=" & AQ$4, 'Regional allocations LIVE'!$R:$R, "<=" & Table14[[#Headers],[30/06/2026]] ) -> 0 | AR7: =SUMIFS('Regional allocations LIVE'!$T:$T, 'Regional allocations LIVE'!$H:$H, $R7, 'Regional allocations LIVE'!$R:$R, ">=" & AR$4, 'Regional allocations LIVE'!$R:$R, "<=" & Table14[[#Headers],[31/07/2026]] ) -> 0 | AS7: =SUMIFS('Regional allocations LIVE'!$T:$T, 'Regional allocations LIVE'!$H:$H, $R7, 'Regional allocations LIVE'!$R:$R, ">=" & AS$4, 'Regional allocations LIVE'!$R:$R, "<=" & Table14[[#Headers],[31/08/2026]] ) -> 0 | AT7: =SUMIFS('Regional allocations LIVE'!$T:$T, 'Regional allocations LIVE'!$H:$H, $R7, 'Regional allocations LIVE'!$R:$R, ">=" & AT$4, 'Regional allocations LIVE'!$R:$R, "<=" & Table14[[#Headers],[30/09/2026]] ) -> 0 | AU7: =SUMIFS('Regional allocations LIVE'!$T:$T, 'Regional allocations LIVE'!$H:$H, $R7, 'Regional allocations LIVE'!$R:$R, ">=" & AU$4, 'Regional allocations LIVE'!$R:$R, "<=" & Table14[[#Headers],[31/10/2026]] ) -> 0 | AV7: =SUMIFS('Regional allocations LIVE'!$T:$T, 'Regional allocations LIVE'!$H:$H, $R7, 'Regional allocations LIVE'!$R:$R, ">=" & AV$4, 'Regional allocations LIVE'!$R:$R, "<=" & Table14[[#Headers],[30/11/2026]] ) -> 0 | AW7: =SUMIFS('Regional allocations LIVE'!$T:$T, 'Regional allocations LIVE'!$H:$H, $R7, 'Regional allocations LIVE'!$R:$R, ">=" & AW$4, 'Regional allocations LIVE'!$R:$R, "<=" & Table14[[#Headers],[31/12/2026]] ) -> 0 | AX7: =SUMIFS('Regional allocations LIVE'!$T:$T, 'Regional allocations LIVE'!$H:$H, $R7, 'Regional allocations LIVE'!$R:$R, ">=" & AX$4, 'Regional allocations LIVE'!$R:$R, "<=" & Table14[[#Headers],[30/01/2027]] ) -> 0 | AY7: =SUMIFS('Regional allocations LIVE'!$T:$T, 'Regional allocations LIVE'!$H:$H, $R7, 'Regional allocations LIVE'!$R:$R, ">=" & AY$4, 'Regional allocations LIVE'!$R:$R, "<=" & Table14[[#Headers],[28/02/2027]] ) -> 0 | AZ7: =SUMIFS('Regional allocations LIVE'!$T:$T, 'Regional allocations LIVE'!$H:$H, $R7, 'Regional allocations LIVE'!$R:$R, ">=" & AZ$4, 'Regional allocations LIVE'!$R:$R, "<=" & Table14[[#Headers],[31/03/2027]] ) -> 0 | BA7: =SUMIFS('Regional allocations LIVE'!$T:$T, 'Regional allocations LIVE'!$H:$H, $R7, 'Regional allocations LIVE'!$R:$R, ">=" & BA$4, 'Regional allocations LIVE'!$R:$R, "<=" & Table14[[#Headers],[30/04/2027]] ) -> 0 | BB7: =SUMIFS('Regional allocations LIVE'!$T:$T, 'Regional allocations LIVE'!$H:$H, $R7, 'Regional allocations LIVE'!$R:$R, ">=" & BB$4, 'Regional allocations LIVE'!$R:$R, "<=" & Table14[[#Headers],[31/05/2027]] ) -> 0 | BC7: =SUMIFS('Regional allocations LIVE'!$T:$T, 'Regional allocations LIVE'!$H:$H, $R7, 'Regional allocations LIVE'!$R:$R, ">=" & BC$4, 'Regional allocations LIVE'!$R:$R, "<=" & Table14[[#Headers],[30/06/2027]] ) -> 0 | BD7: =SUMIFS('Regional allocations LIVE'!$T:$T, 'Regional allocations LIVE'!$H:$H, $R7, 'Regional allocations LIVE'!$R:$R, ">=" & BD$4, 'Regional allocations LIVE'!$R:$R, "<=" & Table14[[#Headers],[31/07/2027]] ) -> 0 | BE7: =SUMIFS('Regional allocations LIVE'!$T:$T, 'Regional allocations LIVE'!$H:$H, $R7, 'Regional allocations LIVE'!$R:$R, ">=" & BE$4, 'Regional allocations LIVE'!$R:$R, "<=" & Table14[[#Headers],[31/08/2027]] ) -> 0 | BF7: =SUMIFS('Regional allocations LIVE'!$T:$T, 'Regional allocations LIVE'!$H:$H, $R7, 'Regional allocations LIVE'!$R:$R, ">=" & BF$4, 'Regional allocations LIVE'!$R:$R, "<=" & Table14[[#Headers],[30/09/2027]] ) -> 0 | BG7: =SUMIFS('Regional allocations LIVE'!$T:$T, 'Regional allocations LIVE'!$H:$H, $R7, 'Regional allocations LIVE'!$R:$R, ">=" & BG$4, 'Regional allocations LIVE'!$R:$R, "<=" & Table14[[#Headers],[31/10/2027]] ) -> 0
B8: Engineering | C8: =AD40 -> 42.2 | E8: =C11+C12+C14+3 -> 108.55 | H8: Engineering | I8: =COUNTIFS('Regional allocations LIVE'!H:H,Table1116[[#This Row],[Business Unit]],'Regional allocations LIVE'!R:R,"") -> 36 | J8: 4 | L8: 3 | M8: =COUNTIFS('Regional allocations LIVE'!H:H,Table1116[[#This Row],[Business Unit]],'Regional allocations LIVE'!U:U,"Y",'Regional allocations LIVE'!R:R,"") -> 1 | N8: =Table1116[[#This Row],[Headcount]]-Table1116[[#This Row],[Contractors]] -> 35 | O8: =Table1116[[#This Row],[Perm Headcount (minus contractors)]]+Table1116[[#This Row],[Vaccancies to backfill]]+Table1116[[#This Row],[Vaccancies for new roles]] -> 39 | R8: Shared Services | S8: 0 | T8: 1 | U8: 0 | V8: 1 | W8: 0 | Z8: 1 | AC8: 1 | AF8: =SUMIFS('Regional allocations LIVE'!$T:$T, 'Regional allocations LIVE'!$H:$H, $R8, 'Regional allocations LIVE'!$R:$R, ">=" & AF$4, 'Regional allocations LIVE'!$R:$R, "<=" & Table14[[#Headers],[31/07/2025]] ) -> 0 | AG8: =SUMIFS('Regional allocations LIVE'!$T:$T, 'Regional allocations LIVE'!$H:$H, $R8, 'Regional allocations LIVE'!$R:$R, ">=" & AG$4, 'Regional allocations LIVE'!$R:$R, "<=" & Table14[[#Headers],[31/08/2025]] ) -> 0 | AH8: =SUMIFS('Regional allocations LIVE'!$T:$T, 'Regional allocations LIVE'!$H:$H, $R8, 'Regional allocations LIVE'!$R:$R, ">=" & AH$4, 'Regional allocations LIVE'!$R:$R, "<=" & Table14[[#Headers],[30/09/2025]] ) -> 0 | AI8: =SUMIFS('Regional allocations LIVE'!$T:$T, 'Regional allocations LIVE'!$H:$H, $R8, 'Regional allocations LIVE'!$R:$R, ">=" & AI$4, 'Regional allocations LIVE'!$R:$R, "<=" & Table14[[#Headers],[31/10/2025]] ) -> 0 | AJ8: =SUMIFS('Regional allocations LIVE'!$T:$T, 'Regional allocations LIVE'!$H:$H, $R8, 'Regional allocations LIVE'!$R:$R, ">=" & AJ$4, 'Regional allocations LIVE'!$R:$R, "<=" & Table14[[#Headers],[30/11/2025]] ) -> 0 | AK8: =SUMIFS('Regional allocations LIVE'!$T:$T, 'Regional allocations LIVE'!$H:$H, $R8, 'Regional allocations LIVE'!$R:$R, ">=" & AK$4, 'Regional allocations LIVE'!$R:$R, "<=" & Table14[[#Headers],[31/12/2025]] ) -> 0 | AL8: =SUMIFS('Regional allocations LIVE'!$T:$T, 'Regional allocations LIVE'!$H:$H, $R8, 'Regional allocations LIVE'!$R:$R, ">=" & AL$4, 'Regional allocations LIVE'!$R:$R, "<=" & Table14[[#Headers],[30/01/2026]] ) -> 0 | AM8: =SUMIFS('Regional allocations LIVE'!$T:$T, 'Regional allocations LIVE'!$H:$H, $R8, 'Regional allocations LIVE'!$R:$R, ">=" & AM$4, 'Regional allocations LIVE'!$R:$R, "<=" & Table14[[#Headers],[28/02/2026]] ) -> 0 | AN8: =SUMIFS('Regional allocations LIVE'!$T:$T, 'Regional allocations LIVE'!$H:$H, $R8, 'Regional allocations LIVE'!$R:$R, ">=" & AN$4, 'Regional allocations LIVE'!$R:$R, "<=" & Table14[[#Headers],[31/03/2026]] ) -> 0 | AO8: =SUMIFS('Regional allocations LIVE'!$T:$T, 'Regional allocations LIVE'!$H:$H, $R8, 'Regional allocations LIVE'!$R:$R, ">=" & AO$4, 'Regional allocations LIVE'!$R:$R, "<=" & Table14[[#Headers],[30/04/2026]] ) -> 0 | AP8: =SUMIFS('Regional allocations LIVE'!$T:$T, 'Regional allocations LIVE'!$H:$H, $R8, 'Regional allocations LIVE'!$R:$R, ">=" & AP$4, 'Regional allocations LIVE'!$R:$R, "<=" & Table14[[#Headers],[31/05/2026]] ) -> 0 | AQ8: =SUMIFS('Regional allocations LIVE'!$T:$T, 'Regional allocations LIVE'!$H:$H, $R8, 'Regional allocations LIVE'!$R:$R, ">=" & AQ$4, 'Regional allocations LIVE'!$R:$R, "<=" & Table14[[#Headers],[30/06/2026]] ) -> 0 | AR8: =SUMIFS('Regional allocations LIVE'!$T:$T, 'Regional allocations LIVE'!$H:$H, $R8, 'Regional allocations LIVE'!$R:$R, ">=" & AR$4, 'Regional allocations LIVE'!$R:$R, "<=" & Table14[[#Headers],[31/07/2026]] ) -> 0 | AS8: =SUMIFS('Regional allocations LIVE'!$T:$T, 'Regional allocations LIVE'!$H:$H, $R8, 'Regional allocations LIVE'!$R:$R, ">=" & AS$4, 'Regional allocations LIVE'!$R:$R, "<=" & Table14[[#Headers],[31/08/2026]] ) -> 0 | AT8: =SUMIFS('Regional allocations LIVE'!$T:$T, 'Regional allocations LIVE'!$H:$H, $R8, 'Regional allocations LIVE'!$R:$R, ">=" & AT$4, 'Regional allocations LIVE'!$R:$R, "<=" & Table14[[#Headers],[30/09/2026]] ) -> 0 | AU8: =SUMIFS('Regional allocations LIVE'!$T:$T, 'Regional allocations LIVE'!$H:$H, $R8, 'Regional allocations LIVE'!$R:$R, ">=" & AU$4, 'Regional allocations LIVE'!$R:$R, "<=" & Table14[[#Headers],[31/10/2026]] ) -> 0 | AV8: =SUMIFS('Regional allocations LIVE'!$T:$T, 'Regional allocations LIVE'!$H:$H, $R8, 'Regional allocations LIVE'!$R:$R, ">=" & AV$4, 'Regional allocations LIVE'!$R:$R, "<=" & Table14[[#Headers],[30/11/2026]] ) -> 0 | AW8: =SUMIFS('Regional allocations LIVE'!$T:$T, 'Regional allocations LIVE'!$H:$H, $R8, 'Regional allocations LIVE'!$R:$R, ">=" & AW$4, 'Regional allocations LIVE'!$R:$R, "<=" & Table14[[#Headers],[31/12/2026]] ) -> 0 | AX8: =SUMIFS('Regional allocations LIVE'!$T:$T, 'Regional allocations LIVE'!$H:$H, $R8, 'Regional allocations LIVE'!$R:$R, ">=" & AX$4, 'Regional allocations LIVE'!$R:$R, "<=" & Table14[[#Headers],[30/01/2027]] ) -> 0 | AY8: =SUMIFS('Regional allocations LIVE'!$T:$T, 'Regional allocations LIVE'!$H:$H, $R8, 'Regional allocations LIVE'!$R:$R, ">=" & AY$4, 'Regional allocations LIVE'!$R:$R, "<=" & Table14[[#Headers],[28/02/2027]] ) -> 0 | AZ8: =SUMIFS('Regional allocations LIVE'!$T:$T, 'Regional allocations LIVE'!$H:$H, $R8, 'Regional allocations LIVE'!$R:$R, ">=" & AZ$4, 'Regional allocations LIVE'!$R:$R, "<=" & Table14[[#Headers],[31/03/2027]] ) -> 0 | BA8: =SUMIFS('Regional allocations LIVE'!$T:$T, 'Regional allocations LIVE'!$H:$H, $R8, 'Regional allocations LIVE'!$R:$R, ">=" & BA$4, 'Regional allocations LIVE'!$R:$R, "<=" & Table14[[#Headers],[30/04/2027]] ) -> 0 | BB8: =SUMIFS('Regional allocations LIVE'!$T:$T, 'Regional allocations LIVE'!$H:$H, $R8, 'Regional allocations LIVE'!$R:$R, ">=" & BB$4, 'Regional allocations LIVE'!$R:$R, "<=" & Table14[[#Headers],[31/05/2027]] ) -> 0 | BC8: =SUMIFS('Regional allocations LIVE'!$T:$T, 'Regional allocations LIVE'!$H:$H, $R8, 'Regional allocations LIVE'!$R:$R, ">=" & BC$4, 'Regional allocations LIVE'!$R:$R, "<=" & Table14[[#Headers],[30/06/2027]] ) -> 0 | BD8: =SUMIFS('Regional allocations LIVE'!$T:$T, 'Regional allocations LIVE'!$H:$H, $R8, 'Regional allocations LIVE'!$R:$R, ">=" & BD$4, 'Regional allocations LIVE'!$R:$R, "<=" & Table14[[#Headers],[31/07/2027]] ) -> 0 | BE8: =SUMIFS('Regional allocations LIVE'!$T:$T, 'Regional allocations LIVE'!$H:$H, $R8, 'Regional allocations LIVE'!$R:$R, ">=" & BE$4, 'Regional allocations LIVE'!$R:$R, "<=" & Table14[[#Headers],[31/08/2027]] ) -> 0 | BF8: =SUMIFS('Regional allocations LIVE'!$T:$T, 'Regional allocations LIVE'!$H:$H, $R8, 'Regional allocations LIVE'!$R:$R, ">=" & BF$4, 'Regional allocations LIVE'!$R:$R, "<=" & Table14[[#Headers],[30/09/2027]] ) -> 0 | BG8: =SUMIFS('Regional allocations LIVE'!$T:$T, 'Regional allocations LIVE'!$H:$H, $R8, 'Regional allocations LIVE'!$R:$R, ">=" & BG$4, 'Regional allocations LIVE'!$R:$R, "<=" & Table14[[#Headers],[31/10/2027]] ) -> 0
B9: Sales | C9: =AD41 -> 3 | H9: Sales | I9: =COUNTIFS('Regional allocations LIVE'!H:H,Table1116[[#This Row],[Business Unit]],'Regional allocations LIVE'!R:R,"") -> 5 | J9: 1 | K9: 1 | M9: =COUNTIFS('Regional allocations LIVE'!H:H,Table1116[[#This Row],[Business Unit]],'Regional allocations LIVE'!U:U,"Y",'Regional allocations LIVE'!R:R,"") -> 1 | N9: =Table1116[[#This Row],[Headcount]]-Table1116[[#This Row],[Contractors]] -> 4 | O9: =Table1116[[#This Row],[Perm Headcount (minus contractors)]]+Table1116[[#This Row],[Vaccancies to backfill]]+Table1116[[#This Row],[Vaccancies for new roles]] -> 6 | R9: Europe | S9: 2 | T9: 1 | U9: 1 | V9: 0 | W9: 1 | X9: 1 | Z9: 1 | AA9: 1 | AB9: 1 | AC9: 1 | AD9: 1 | AE9: 2 | AF9: =SUMIFS('Regional allocations LIVE'!$T:$T, 'Regional allocations LIVE'!$H:$H, $R9, 'Regional allocations LIVE'!$R:$R, ">=" & AF$4, 'Regional allocations LIVE'!$R:$R, "<=" & Table14[[#Headers],[31/07/2025]] ) -> 0 | AG9: =SUMIFS('Regional allocations LIVE'!$T:$T, 'Regional allocations LIVE'!$H:$H, $R9, 'Regional allocations LIVE'!$R:$R, ">=" & AG$4, 'Regional allocations LIVE'!$R:$R, "<=" & Table14[[#Headers],[31/08/2025]] ) -> 0 | AH9: =SUMIFS('Regional allocations LIVE'!$T:$T, 'Regional allocations LIVE'!$H:$H, $R9, 'Regional allocations LIVE'!$R:$R, ">=" & AH$4, 'Regional allocations LIVE'!$R:$R, "<=" & Table14[[#Headers],[30/09/2025]] ) -> 0 | AI9: =SUMIFS('Regional allocations LIVE'!$T:$T, 'Regional allocations LIVE'!$H:$H, $R9, 'Regional allocations LIVE'!$R:$R, ">=" & AI$4, 'Regional allocations LIVE'!$R:$R, "<=" & Table14[[#Headers],[31/10/2025]] ) -> 1 | AJ9: =SUMIFS('Regional allocations LIVE'!$T:$T, 'Regional allocations LIVE'!$H:$H, $R9, 'Regional allocations LIVE'!$R:$R, ">=" & AJ$4, 'Regional allocations LIVE'!$R:$R, "<=" & Table14[[#Headers],[30/11/2025]] ) -> 0 | AK9: =SUMIFS('Regional allocations LIVE'!$T:$T, 'Regional allocations LIVE'!$H:$H, $R9, 'Regional allocations LIVE'!$R:$R, ">=" & AK$4, 'Regional allocations LIVE'!$R:$R, "<=" & Table14[[#Headers],[31/12/2025]] ) -> 0 | AL9: =SUMIFS('Regional allocations LIVE'!$T:$T, 'Regional allocations LIVE'!$H:$H, $R9, 'Regional allocations LIVE'!$R:$R, ">=" & AL$4, 'Regional allocations LIVE'!$R:$R, "<=" & Table14[[#Headers],[30/01/2026]] ) -> 0 | AM9: =SUMIFS('Regional allocations LIVE'!$T:$T, 'Regional allocations LIVE'!$H:$H, $R9, 'Regional allocations LIVE'!$R:$R, ">=" & AM$4, 'Regional allocations LIVE'!$R:$R, "<=" & Table14[[#Headers],[28/02/2026]] ) -> 0 | AN9: =SUMIFS('Regional allocations LIVE'!$T:$T, 'Regional allocations LIVE'!$H:$H, $R9, 'Regional allocations LIVE'!$R:$R, ">=" & AN$4, 'Regional allocations LIVE'!$R:$R, "<=" & Table14[[#Headers],[31/03/2026]] ) -> 0 | AO9: =SUMIFS('Regional allocations LIVE'!$T:$T, 'Regional allocations LIVE'!$H:$H, $R9, 'Regional allocations LIVE'!$R:$R, ">=" & AO$4, 'Regional allocations LIVE'!$R:$R, "<=" & Table14[[#Headers],[30/04/2026]] ) -> 0 | AP9: =SUMIFS('Regional allocations LIVE'!$T:$T, 'Regional allocations LIVE'!$H:$H, $R9, 'Regional allocations LIVE'!$R:$R, ">=" & AP$4, 'Regional allocations LIVE'!$R:$R, "<=" & Table14[[#Headers],[31/05/2026]] ) -> 0 | AQ9: =SUMIFS('Regional allocations LIVE'!$T:$T, 'Regional allocations LIVE'!$H:$H, $R9, 'Regional allocations LIVE'!$R:$R, ">=" & AQ$4, 'Regional allocations LIVE'!$R:$R, "<=" & Table14[[#Headers],[30/06/2026]] ) -> 0 | AR9: =SUMIFS('Regional allocations LIVE'!$T:$T, 'Regional allocations LIVE'!$H:$H, $R9, 'Regional allocations LIVE'!$R:$R, ">=" & AR$4, 'Regional allocations LIVE'!$R:$R, "<=" & Table14[[#Headers],[31/07/2026]] ) -> 0 | AS9: =SUMIFS('Regional allocations LIVE'!$T:$T, 'Regional allocations LIVE'!$H:$H, $R9, 'Regional allocations LIVE'!$R:$R, ">=" & AS$4, 'Regional allocations LIVE'!$R:$R, "<=" & Table14[[#Headers],[31/08/2026]] ) -> 0 | AT9: =SUMIFS('Regional allocations LIVE'!$T:$T, 'Regional allocations LIVE'!$H:$H, $R9, 'Regional allocations LIVE'!$R:$R, ">=" & AT$4, 'Regional allocations LIVE'!$R:$R, "<=" & Table14[[#Headers],[30/09/2026]] ) -> 0 | AU9: =SUMIFS('Regional allocations LIVE'!$T:$T, 'Regional allocations LIVE'!$H:$H, $R9, 'Regional allocations LIVE'!$R:$R, ">=" & AU$4, 'Regional allocations LIVE'!$R:$R, "<=" & Table14[[#Headers],[31/10/2026]] ) -> 0 | AV9: =SUMIFS('Regional allocations LIVE'!$T:$T, 'Regional allocations LIVE'!$H:$H, $R9, 'Regional allocations LIVE'!$R:$R, ">=" & AV$4, 'Regional allocations LIVE'!$R:$R, "<=" & Table14[[#Headers],[30/11/2026]] ) -> 0 | AW9: =SUMIFS('Regional allocations LIVE'!$T:$T, 'Regional allocations LIVE'!$H:$H, $R9, 'Regional allocations LIVE'!$R:$R, ">=" & AW$4, 'Regional allocations LIVE'!$R:$R, "<=" & Table14[[#Headers],[31/12/2026]] ) -> 0 | AX9: =SUMIFS('Regional allocations LIVE'!$T:$T, 'Regional allocations LIVE'!$H:$H, $R9, 'Regional allocations LIVE'!$R:$R, ">=" & AX$4, 'Regional allocations LIVE'!$R:$R, "<=" & Table14[[#Headers],[30/01/2027]] ) -> 0 | AY9: =SUMIFS('Regional allocations LIVE'!$T:$T, 'Regional allocations LIVE'!$H:$H, $R9, 'Regional allocations LIVE'!$R:$R, ">=" & AY$4, 'Regional allocations LIVE'!$R:$R, "<=" & Table14[[#Headers],[28/02/2027]] ) -> 0 | AZ9: =SUMIFS('Regional allocations LIVE'!$T:$T, 'Regional allocations LIVE'!$H:$H, $R9, 'Regional allocations LIVE'!$R:$R, ">=" & AZ$4, 'Regional allocations LIVE'!$R:$R, "<=" & Table14[[#Headers],[31/03/2027]] ) -> 0 | BA9: =SUMIFS('Regional allocations LIVE'!$T:$T, 'Regional allocations LIVE'!$H:$H, $R9, 'Regional allocations LIVE'!$R:$R, ">=" & BA$4, 'Regional allocations LIVE'!$R:$R, "<=" & Table14[[#Headers],[30/04/2027]] ) -> 0 | BB9: =SUMIFS('Regional allocations LIVE'!$T:$T, 'Regional allocations LIVE'!$H:$H, $R9, 'Regional allocations LIVE'!$R:$R, ">=" & BB$4, 'Regional allocations LIVE'!$R:$R, "<=" & Table14[[#Headers],[31/05/2027]] ) -> 0 | BC9: =SUMIFS('Regional allocations LIVE'!$T:$T, 'Regional allocations LIVE'!$H:$H, $R9, 'Regional allocations LIVE'!$R:$R, ">=" & BC$4, 'Regional allocations LIVE'!$R:$R, "<=" & Table14[[#Headers],[30/06/2027]] ) -> 0 | BD9: =SUMIFS('Regional allocations LIVE'!$T:$T, 'Regional allocations LIVE'!$H:$H, $R9, 'Regional allocations LIVE'!$R:$R, ">=" & BD$4, 'Regional allocations LIVE'!$R:$R, "<=" & Table14[[#Headers],[31/07/2027]] ) -> 0 | BE9: =SUMIFS('Regional allocations LIVE'!$T:$T, 'Regional allocations LIVE'!$H:$H, $R9, 'Regional allocations LIVE'!$R:$R, ">=" & BE$4, 'Regional allocations LIVE'!$R:$R, "<=" & Table14[[#Headers],[31/08/2027]] ) -> 0 | BF9: =SUMIFS('Regional allocations LIVE'!$T:$T, 'Regional allocations LIVE'!$H:$H, $R9, 'Regional allocations LIVE'!$R:$R, ">=" & BF$4, 'Regional allocations LIVE'!$R:$R, "<=" & Table14[[#Headers],[30/09/2027]] ) -> 0 | BG9: =SUMIFS('Regional allocations LIVE'!$T:$T, 'Regional allocations LIVE'!$H:$H, $R9, 'Regional allocations LIVE'!$R:$R, ">=" & BG$4, 'Regional allocations LIVE'!$R:$R, "<=" & Table14[[#Headers],[31/10/2027]] ) -> 0
B10: Shared Services | C10: =AD42 -> 16 | E10: Total Headcount | H10: Shared Services | I10: =COUNTIFS('Regional allocations LIVE'!H:H,Table1116[[#This Row],[Business Unit]],'Regional allocations LIVE'!R:R,"") -> 16 | J10: 1 | M10: =COUNTIFS('Regional allocations LIVE'!H:H,Table1116[[#This Row],[Business Unit]],'Regional allocations LIVE'!U:U,"Y",'Regional allocations LIVE'!R:R,"") -> 0 | N10: =Table1116[[#This Row],[Headcount]]-Table1116[[#This Row],[Contractors]] -> 16 | O10: =Table1116[[#This Row],[Perm Headcount (minus contractors)]]+Table1116[[#This Row],[Vaccancies to backfill]]+Table1116[[#This Row],[Vaccancies for new roles]] -> 17 | R10: Asia Pacific | S10: 0 | T10: 0 | U10: 0 | V10: 1 | W10: 0 | Y10: 1 | Z10: 2 | AE10: 1 | AF10: =SUMIFS('Regional allocations LIVE'!$T:$T, 'Regional allocations LIVE'!$H:$H, $R10, 'Regional allocations LIVE'!$R:$R, ">=" & AF$4, 'Regional allocations LIVE'!$R:$R, "<=" & Table14[[#Headers],[31/07/2025]] ) -> 0 | AG10: =SUMIFS('Regional allocations LIVE'!$T:$T, 'Regional allocations LIVE'!$H:$H, $R10, 'Regional allocations LIVE'!$R:$R, ">=" & AG$4, 'Regional allocations LIVE'!$R:$R, "<=" & Table14[[#Headers],[31/08/2025]] ) -> 0 | AH10: =SUMIFS('Regional allocations LIVE'!$T:$T, 'Regional allocations LIVE'!$H:$H, $R10, 'Regional allocations LIVE'!$R:$R, ">=" & AH$4, 'Regional allocations LIVE'!$R:$R, "<=" & Table14[[#Headers],[30/09/2025]] ) -> 0 | AI10: =SUMIFS('Regional allocations LIVE'!$T:$T, 'Regional allocations LIVE'!$H:$H, $R10, 'Regional allocations LIVE'!$R:$R, ">=" & AI$4, 'Regional allocations LIVE'!$R:$R, "<=" & Table14[[#Headers],[31/10/2025]] ) -> 0 | AJ10: =SUMIFS('Regional allocations LIVE'!$T:$T, 'Regional allocations LIVE'!$H:$H, $R10, 'Regional allocations LIVE'!$R:$R, ">=" & AJ$4, 'Regional allocations LIVE'!$R:$R, "<=" & Table14[[#Headers],[30/11/2025]] ) -> 0 | AK10: =SUMIFS('Regional allocations LIVE'!$T:$T, 'Regional allocations LIVE'!$H:$H, $R10, 'Regional allocations LIVE'!$R:$R, ">=" & AK$4, 'Regional allocations LIVE'!$R:$R, "<=" & Table14[[#Headers],[31/12/2025]] ) -> 0 | AL10: =SUMIFS('Regional allocations LIVE'!$T:$T, 'Regional allocations LIVE'!$H:$H, $R10, 'Regional allocations LIVE'!$R:$R, ">=" & AL$4, 'Regional allocations LIVE'!$R:$R, "<=" & Table14[[#Headers],[30/01/2026]] ) -> 0 | AM10: =SUMIFS('Regional allocations LIVE'!$T:$T, 'Regional allocations LIVE'!$H:$H, $R10, 'Regional allocations LIVE'!$R:$R, ">=" & AM$4, 'Regional allocations LIVE'!$R:$R, "<=" & Table14[[#Headers],[28/02/2026]] ) -> 0 | AN10: =SUMIFS('Regional allocations LIVE'!$T:$T, 'Regional allocations LIVE'!$H:$H, $R10, 'Regional allocations LIVE'!$R:$R, ">=" & AN$4, 'Regional allocations LIVE'!$R:$R, "<=" & Table14[[#Headers],[31/03/2026]] ) -> 0 | AO10: =SUMIFS('Regional allocations LIVE'!$T:$T, 'Regional allocations LIVE'!$H:$H, $R10, 'Regional allocations LIVE'!$R:$R, ">=" & AO$4, 'Regional allocations LIVE'!$R:$R, "<=" & Table14[[#Headers],[30/04/2026]] ) -> 0 | AP10: =SUMIFS('Regional allocations LIVE'!$T:$T, 'Regional allocations LIVE'!$H:$H, $R10, 'Regional allocations LIVE'!$R:$R, ">=" & AP$4, 'Regional allocations LIVE'!$R:$R, "<=" & Table14[[#Headers],[31/05/2026]] ) -> 0 | AQ10: =SUMIFS('Regional allocations LIVE'!$T:$T, 'Regional allocations LIVE'!$H:$H, $R10, 'Regional allocations LIVE'!$R:$R, ">=" & AQ$4, 'Regional allocations LIVE'!$R:$R, "<=" & Table14[[#Headers],[30/06/2026]] ) -> 0 | AR10: =SUMIFS('Regional allocations LIVE'!$T:$T, 'Regional allocations LIVE'!$H:$H, $R10, 'Regional allocations LIVE'!$R:$R, ">=" & AR$4, 'Regional allocations LIVE'!$R:$R, "<=" & Table14[[#Headers],[31/07/2026]] ) -> 0 | AS10: =SUMIFS('Regional allocations LIVE'!$T:$T, 'Regional allocations LIVE'!$H:$H, $R10, 'Regional allocations LIVE'!$R:$R, ">=" & AS$4, 'Regional allocations LIVE'!$R:$R, "<=" & Table14[[#Headers],[31/08/2026]] ) -> 0 | AT10: =SUMIFS('Regional allocations LIVE'!$T:$T, 'Regional allocations LIVE'!$H:$H, $R10, 'Regional allocations LIVE'!$R:$R, ">=" & AT$4, 'Regional allocations LIVE'!$R:$R, "<=" & Table14[[#Headers],[30/09/2026]] ) -> 0 | AU10: =SUMIFS('Regional allocations LIVE'!$T:$T, 'Regional allocations LIVE'!$H:$H, $R10, 'Regional allocations LIVE'!$R:$R, ">=" & AU$4, 'Regional allocations LIVE'!$R:$R, "<=" & Table14[[#Headers],[31/10/2026]] ) -> 0 | AV10: =SUMIFS('Regional allocations LIVE'!$T:$T, 'Regional allocations LIVE'!$H:$H, $R10, 'Regional allocations LIVE'!$R:$R, ">=" & AV$4, 'Regional allocations LIVE'!$R:$R, "<=" & Table14[[#Headers],[30/11/2026]] ) -> 0 | AW10: =SUMIFS('Regional allocations LIVE'!$T:$T, 'Regional allocations LIVE'!$H:$H, $R10, 'Regional allocations LIVE'!$R:$R, ">=" & AW$4, 'Regional allocations LIVE'!$R:$R, "<=" & Table14[[#Headers],[31/12/2026]] ) -> 0 | AX10: =SUMIFS('Regional allocations LIVE'!$T:$T, 'Regional allocations LIVE'!$H:$H, $R10, 'Regional allocations LIVE'!$R:$R, ">=" & AX$4, 'Regional allocations LIVE'!$R:$R, "<=" & Table14[[#Headers],[30/01/2027]] ) -> 0 | AY10: =SUMIFS('Regional allocations LIVE'!$T:$T, 'Regional allocations LIVE'!$H:$H, $R10, 'Regional allocations LIVE'!$R:$R, ">=" & AY$4, 'Regional allocations LIVE'!$R:$R, "<=" & Table14[[#Headers],[28/02/2027]] ) -> 0 | AZ10: =SUMIFS('Regional allocations LIVE'!$T:$T, 'Regional allocations LIVE'!$H:$H, $R10, 'Regional allocations LIVE'!$R:$R, ">=" & AZ$4, 'Regional allocations LIVE'!$R:$R, "<=" & Table14[[#Headers],[31/03/2027]] ) -> 0 | BA10: =SUMIFS('Regional allocations LIVE'!$T:$T, 'Regional allocations LIVE'!$H:$H, $R10, 'Regional allocations LIVE'!$R:$R, ">=" & BA$4, 'Regional allocations LIVE'!$R:$R, "<=" & Table14[[#Headers],[30/04/2027]] ) -> 0 | BB10: =SUMIFS('Regional allocations LIVE'!$T:$T, 'Regional allocations LIVE'!$H:$H, $R10, 'Regional allocations LIVE'!$R:$R, ">=" & BB$4, 'Regional allocations LIVE'!$R:$R, "<=" & Table14[[#Headers],[31/05/2027]] ) -> 0 | BC10: =SUMIFS('Regional allocations LIVE'!$T:$T, 'Regional allocations LIVE'!$H:$H, $R10, 'Regional allocations LIVE'!$R:$R, ">=" & BC$4, 'Regional allocations LIVE'!$R:$R, "<=" & Table14[[#Headers],[30/06/2027]] ) -> 0 | BD10: =SUMIFS('Regional allocations LIVE'!$T:$T, 'Regional allocations LIVE'!$H:$H, $R10, 'Regional allocations LIVE'!$R:$R, ">=" & BD$4, 'Regional allocations LIVE'!$R:$R, "<=" & Table14[[#Headers],[31/07/2027]] ) -> 0 | BE10: =SUMIFS('Regional allocations LIVE'!$T:$T, 'Regional allocations LIVE'!$H:$H, $R10, 'Regional allocations LIVE'!$R:$R, ">=" & BE$4, 'Regional allocations LIVE'!$R:$R, "<=" & Table14[[#Headers],[31/08/2027]] ) -> 0 | BF10: =SUMIFS('Regional allocations LIVE'!$T:$T, 'Regional allocations LIVE'!$H:$H, $R10, 'Regional allocations LIVE'!$R:$R, ">=" & BF$4, 'Regional allocations LIVE'!$R:$R, "<=" & Table14[[#Headers],[30/09/2027]] ) -> 0 | BG10: =SUMIFS('Regional allocations LIVE'!$T:$T, 'Regional allocations LIVE'!$H:$H, $R10, 'Regional allocations LIVE'!$R:$R, ">=" & BG$4, 'Regional allocations LIVE'!$R:$R, "<=" & Table14[[#Headers],[31/10/2027]] ) -> 0
B11: Europe | C11: =AD43 -> 44.8 | E11: =SUM(Table11[Headcount]) -> 170.75 | H11: Europe | I11: =COUNTIFS('Regional allocations LIVE'!H:H,Table1116[[#This Row],[Business Unit]],'Regional allocations LIVE'!R:R,"") -> 49 | J11: 5 | K11: 2 | M11: =COUNTIFS('Regional allocations LIVE'!H:H,Table1116[[#This Row],[Business Unit]],'Regional allocations LIVE'!U:U,"Y",'Regional allocations LIVE'!R:R,"") -> 0 | N11: =Table1116[[#This Row],[Headcount]]-Table1116[[#This Row],[Contractors]] -> 49 | O11: =Table1116[[#This Row],[Perm Headcount (minus contractors)]]+Table1116[[#This Row],[Vaccancies to backfill]]+Table1116[[#This Row],[Vaccancies for new roles]] -> 56 | R11: ELT | S11: 0 | T11: 0 | U11: 0 | V11: 0 | W11: 0 | AA11: 1 | AF11: =SUMIFS('Regional allocations LIVE'!$T:$T, 'Regional allocations LIVE'!$H:$H, $R11, 'Regional allocations LIVE'!$R:$R, ">=" & AF$4, 'Regional allocations LIVE'!$R:$R, "<=" & Table14[[#Headers],[31/07/2025]] ) -> 0 | AG11: =SUMIFS('Regional allocations LIVE'!$T:$T, 'Regional allocations LIVE'!$H:$H, $R11, 'Regional allocations LIVE'!$R:$R, ">=" & AG$4, 'Regional allocations LIVE'!$R:$R, "<=" & Table14[[#Headers],[31/08/2025]] ) -> 0 | AH11: =SUMIFS('Regional allocations LIVE'!$T:$T, 'Regional allocations LIVE'!$H:$H, $R11, 'Regional allocations LIVE'!$R:$R, ">=" & AH$4, 'Regional allocations LIVE'!$R:$R, "<=" & Table14[[#Headers],[30/09/2025]] ) -> 0 | AI11: =SUMIFS('Regional allocations LIVE'!$T:$T, 'Regional allocations LIVE'!$H:$H, $R11, 'Regional allocations LIVE'!$R:$R, ">=" & AI$4, 'Regional allocations LIVE'!$R:$R, "<=" & Table14[[#Headers],[31/10/2025]] ) -> 0 | AJ11: =SUMIFS('Regional allocations LIVE'!$T:$T, 'Regional allocations LIVE'!$H:$H, $R11, 'Regional allocations LIVE'!$R:$R, ">=" & AJ$4, 'Regional allocations LIVE'!$R:$R, "<=" & Table14[[#Headers],[30/11/2025]] ) -> 0 | AK11: =SUMIFS('Regional allocations LIVE'!$T:$T, 'Regional allocations LIVE'!$H:$H, $R11, 'Regional allocations LIVE'!$R:$R, ">=" & AK$4, 'Regional allocations LIVE'!$R:$R, "<=" & Table14[[#Headers],[31/12/2025]] ) -> 0 | AL11: =SUMIFS('Regional allocations LIVE'!$T:$T, 'Regional allocations LIVE'!$H:$H, $R11, 'Regional allocations LIVE'!$R:$R, ">=" & AL$4, 'Regional allocations LIVE'!$R:$R, "<=" & Table14[[#Headers],[30/01/2026]] ) -> 0 | AM11: =SUMIFS('Regional allocations LIVE'!$T:$T, 'Regional allocations LIVE'!$H:$H, $R11, 'Regional allocations LIVE'!$R:$R, ">=" & AM$4, 'Regional allocations LIVE'!$R:$R, "<=" & Table14[[#Headers],[28/02/2026]] ) -> 0 | AN11: =SUMIFS('Regional allocations LIVE'!$T:$T, 'Regional allocations LIVE'!$H:$H, $R11, 'Regional allocations LIVE'!$R:$R, ">=" & AN$4, 'Regional allocations LIVE'!$R:$R, "<=" & Table14[[#Headers],[31/03/2026]] ) -> 0 | AO11: =SUMIFS('Regional allocations LIVE'!$T:$T, 'Regional allocations LIVE'!$H:$H, $R11, 'Regional allocations LIVE'!$R:$R, ">=" & AO$4, 'Regional allocations LIVE'!$R:$R, "<=" & Table14[[#Headers],[30/04/2026]] ) -> 0 | AP11: =SUMIFS('Regional allocations LIVE'!$T:$T, 'Regional allocations LIVE'!$H:$H, $R11, 'Regional allocations LIVE'!$R:$R, ">=" & AP$4, 'Regional allocations LIVE'!$R:$R, "<=" & Table14[[#Headers],[31/05/2026]] ) -> 0 | AQ11: =SUMIFS('Regional allocations LIVE'!$T:$T, 'Regional allocations LIVE'!$H:$H, $R11, 'Regional allocations LIVE'!$R:$R, ">=" & AQ$4, 'Regional allocations LIVE'!$R:$R, "<=" & Table14[[#Headers],[30/06/2026]] ) -> 0 | AR11: =SUMIFS('Regional allocations LIVE'!$T:$T, 'Regional allocations LIVE'!$H:$H, $R11, 'Regional allocations LIVE'!$R:$R, ">=" & AR$4, 'Regional allocations LIVE'!$R:$R, "<=" & Table14[[#Headers],[31/07/2026]] ) -> 0 | AS11: =SUMIFS('Regional allocations LIVE'!$T:$T, 'Regional allocations LIVE'!$H:$H, $R11, 'Regional allocations LIVE'!$R:$R, ">=" & AS$4, 'Regional allocations LIVE'!$R:$R, "<=" & Table14[[#Headers],[31/08/2026]] ) -> 0 | AT11: =SUMIFS('Regional allocations LIVE'!$T:$T, 'Regional allocations LIVE'!$H:$H, $R11, 'Regional allocations LIVE'!$R:$R, ">=" & AT$4, 'Regional allocations LIVE'!$R:$R, "<=" & Table14[[#Headers],[30/09/2026]] ) -> 0 | AU11: =SUMIFS('Regional allocations LIVE'!$T:$T, 'Regional allocations LIVE'!$H:$H, $R11, 'Regional allocations LIVE'!$R:$R, ">=" & AU$4, 'Regional allocations LIVE'!$R:$R, "<=" & Table14[[#Headers],[31/10/2026]] ) -> 0 | AV11: =SUMIFS('Regional allocations LIVE'!$T:$T, 'Regional allocations LIVE'!$H:$H, $R11, 'Regional allocations LIVE'!$R:$R, ">=" & AV$4, 'Regional allocations LIVE'!$R:$R, "<=" & Table14[[#Headers],[30/11/2026]] ) -> 0 | AW11: =SUMIFS('Regional allocations LIVE'!$T:$T, 'Regional allocations LIVE'!$H:$H, $R11, 'Regional allocations LIVE'!$R:$R, ">=" & AW$4, 'Regional allocations LIVE'!$R:$R, "<=" & Table14[[#Headers],[31/12/2026]] ) -> 0 | AX11: =SUMIFS('Regional allocations LIVE'!$T:$T, 'Regional allocations LIVE'!$H:$H, $R11, 'Regional allocations LIVE'!$R:$R, ">=" & AX$4, 'Regional allocations LIVE'!$R:$R, "<=" & Table14[[#Headers],[30/01/2027]] ) -> 0 | AY11: =SUMIFS('Regional allocations LIVE'!$T:$T, 'Regional allocations LIVE'!$H:$H, $R11, 'Regional allocations LIVE'!$R:$R, ">=" & AY$4, 'Regional allocations LIVE'!$R:$R, "<=" & Table14[[#Headers],[28/02/2027]] ) -> 0 | AZ11: =SUMIFS('Regional allocations LIVE'!$T:$T, 'Regional allocations LIVE'!$H:$H, $R11, 'Regional allocations LIVE'!$R:$R, ">=" & AZ$4, 'Regional allocations LIVE'!$R:$R, "<=" & Table14[[#Headers],[31/03/2027]] ) -> 0 | BA11: =SUMIFS('Regional allocations LIVE'!$T:$T, 'Regional allocations LIVE'!$H:$H, $R11, 'Regional allocations LIVE'!$R:$R, ">=" & BA$4, 'Regional allocations LIVE'!$R:$R, "<=" & Table14[[#Headers],[30/04/2027]] ) -> 0 | BB11: =SUMIFS('Regional allocations LIVE'!$T:$T, 'Regional allocations LIVE'!$H:$H, $R11, 'Regional allocations LIVE'!$R:$R, ">=" & BB$4, 'Regional allocations LIVE'!$R:$R, "<=" & Table14[[#Headers],[31/05/2027]] ) -> 0 | BC11: =SUMIFS('Regional allocations LIVE'!$T:$T, 'Regional allocations LIVE'!$H:$H, $R11, 'Regional allocations LIVE'!$R:$R, ">=" & BC$4, 'Regional allocations LIVE'!$R:$R, "<=" & Table14[[#Headers],[30/06/2027]] ) -> 0 | BD11: =SUMIFS('Regional allocations LIVE'!$T:$T, 'Regional allocations LIVE'!$H:$H, $R11, 'Regional allocations LIVE'!$R:$R, ">=" & BD$4, 'Regional allocations LIVE'!$R:$R, "<=" & Table14[[#Headers],[31/07/2027]] ) -> 0 | BE11: =SUMIFS('Regional allocations LIVE'!$T:$T, 'Regional allocations LIVE'!$H:$H, $R11, 'Regional allocations LIVE'!$R:$R, ">=" & BE$4, 'Regional allocations LIVE'!$R:$R, "<=" & Table14[[#Headers],[31/08/2027]] ) -> 0 | BF11: =SUMIFS('Regional allocations LIVE'!$T:$T, 'Regional allocations LIVE'!$H:$H, $R11, 'Regional allocations LIVE'!$R:$R, ">=" & BF$4, 'Regional allocations LIVE'!$R:$R, "<=" & Table14[[#Headers],[30/09/2027]] ) -> 0 | BG11: =SUMIFS('Regional allocations LIVE'!$T:$T, 'Regional allocations LIVE'!$H:$H, $R11, 'Regional allocations LIVE'!$R:$R, ">=" & BG$4, 'Regional allocations LIVE'!$R:$R, "<=" & Table14[[#Headers],[31/10/2027]] ) -> 0
B12: Asia Pacific | C12: =AD44 -> 19.75 | H12: Asia Pacific | I12: =COUNTIFS('Regional allocations LIVE'!H:H,Table1116[[#This Row],[Business Unit]],'Regional allocations LIVE'!R:R,"") -> 18 | J12: 0 | M12: =COUNTIFS('Regional allocations LIVE'!H:H,Table1116[[#This Row],[Business Unit]],'Regional allocations LIVE'!U:U,"Y",'Regional allocations LIVE'!R:R,"") -> 0 | N12: =Table1116[[#This Row],[Headcount]]-Table1116[[#This Row],[Contractors]] -> 18 | O12: =Table1116[[#This Row],[Perm Headcount (minus contractors)]]+Table1116[[#This Row],[Vaccancies to backfill]]+Table1116[[#This Row],[Vaccancies for new roles]] -> 18 | R12: Americas | S12: 0 | T12: 1 | U12: 0 | V12: 1 | W12: 0 | AD12: 1 | AE12: 2 | AF12: =SUMIFS('Regional allocations LIVE'!$T:$T, 'Regional allocations LIVE'!$H:$H, $R12, 'Regional allocations LIVE'!$R:$R, ">=" & AF$4, 'Regional allocations LIVE'!$R:$R, "<=" & Table14[[#Headers],[31/07/2025]] ) -> 1 | AG12: =SUMIFS('Regional allocations LIVE'!$T:$T, 'Regional allocations LIVE'!$H:$H, $R12, 'Regional allocations LIVE'!$R:$R, ">=" & AG$4, 'Regional allocations LIVE'!$R:$R, "<=" & Table14[[#Headers],[31/08/2025]] ) -> 1 | AH12: =SUMIFS('Regional allocations LIVE'!$T:$T, 'Regional allocations LIVE'!$H:$H, $R12, 'Regional allocations LIVE'!$R:$R, ">=" & AH$4, 'Regional allocations LIVE'!$R:$R, "<=" & Table14[[#Headers],[30/09/2025]] ) -> 1 | AI12: =SUMIFS('Regional allocations LIVE'!$T:$T, 'Regional allocations LIVE'!$H:$H, $R12, 'Regional allocations LIVE'!$R:$R, ">=" & AI$4, 'Regional allocations LIVE'!$R:$R, "<=" & Table14[[#Headers],[31/10/2025]] ) -> 2 | AJ12: =SUMIFS('Regional allocations LIVE'!$T:$T, 'Regional allocations LIVE'!$H:$H, $R12, 'Regional allocations LIVE'!$R:$R, ">=" & AJ$4, 'Regional allocations LIVE'!$R:$R, "<=" & Table14[[#Headers],[30/11/2025]] ) -> 1 | AK12: =SUMIFS('Regional allocations LIVE'!$T:$T, 'Regional allocations LIVE'!$H:$H, $R12, 'Regional allocations LIVE'!$R:$R, ">=" & AK$4, 'Regional allocations LIVE'!$R:$R, "<=" & Table14[[#Headers],[31/12/2025]] ) -> 1 | AL12: =SUMIFS('Regional allocations LIVE'!$T:$T, 'Regional allocations LIVE'!$H:$H, $R12, 'Regional allocations LIVE'!$R:$R, ">=" & AL$4, 'Regional allocations LIVE'!$R:$R, "<=" & Table14[[#Headers],[30/01/2026]] ) -> 1 | AM12: =SUMIFS('Regional allocations LIVE'!$T:$T, 'Regional allocations LIVE'!$H:$H, $R12, 'Regional allocations LIVE'!$R:$R, ">=" & AM$4, 'Regional allocations LIVE'!$R:$R, "<=" & Table14[[#Headers],[28/02/2026]] ) -> 0 | AN12: =SUMIFS('Regional allocations LIVE'!$T:$T, 'Regional allocations LIVE'!$H:$H, $R12, 'Regional allocations LIVE'!$R:$R, ">=" & AN$4, 'Regional allocations LIVE'!$R:$R, "<=" & Table14[[#Headers],[31/03/2026]] ) -> 0 | AO12: =SUMIFS('Regional allocations LIVE'!$T:$T, 'Regional allocations LIVE'!$H:$H, $R12, 'Regional allocations LIVE'!$R:$R, ">=" & AO$4, 'Regional allocations LIVE'!$R:$R, "<=" & Table14[[#Headers],[30/04/2026]] ) -> 0 | AP12: =SUMIFS('Regional allocations LIVE'!$T:$T, 'Regional allocations LIVE'!$H:$H, $R12, 'Regional allocations LIVE'!$R:$R, ">=" & AP$4, 'Regional allocations LIVE'!$R:$R, "<=" & Table14[[#Headers],[31/05/2026]] ) -> 0 | AQ12: =SUMIFS('Regional allocations LIVE'!$T:$T, 'Regional allocations LIVE'!$H:$H, $R12, 'Regional allocations LIVE'!$R:$R, ">=" & AQ$4, 'Regional allocations LIVE'!$R:$R, "<=" & Table14[[#Headers],[30/06/2026]] ) -> 0 | AR12: =SUMIFS('Regional allocations LIVE'!$T:$T, 'Regional allocations LIVE'!$H:$H, $R12, 'Regional allocations LIVE'!$R:$R, ">=" & AR$4, 'Regional allocations LIVE'!$R:$R, "<=" & Table14[[#Headers],[31/07/2026]] ) -> 0 | AS12: =SUMIFS('Regional allocations LIVE'!$T:$T, 'Regional allocations LIVE'!$H:$H, $R12, 'Regional allocations LIVE'!$R:$R, ">=" & AS$4, 'Regional allocations LIVE'!$R:$R, "<=" & Table14[[#Headers],[31/08/2026]] ) -> 0 | AT12: =SUMIFS('Regional allocations LIVE'!$T:$T, 'Regional allocations LIVE'!$H:$H, $R12, 'Regional allocations LIVE'!$R:$R, ">=" & AT$4, 'Regional allocations LIVE'!$R:$R, "<=" & Table14[[#Headers],[30/09/2026]] ) -> 0 | AU12: =SUMIFS('Regional allocations LIVE'!$T:$T, 'Regional allocations LIVE'!$H:$H, $R12, 'Regional allocations LIVE'!$R:$R, ">=" & AU$4, 'Regional allocations LIVE'!$R:$R, "<=" & Table14[[#Headers],[31/10/2026]] ) -> 0 | AV12: =SUMIFS('Regional allocations LIVE'!$T:$T, 'Regional allocations LIVE'!$H:$H, $R12, 'Regional allocations LIVE'!$R:$R, ">=" & AV$4, 'Regional allocations LIVE'!$R:$R, "<=" & Table14[[#Headers],[30/11/2026]] ) -> 0 | AW12: =SUMIFS('Regional allocations LIVE'!$T:$T, 'Regional allocations LIVE'!$H:$H, $R12, 'Regional allocations LIVE'!$R:$R, ">=" & AW$4, 'Regional allocations LIVE'!$R:$R, "<=" & Table14[[#Headers],[31/12/2026]] ) -> 0 | AX12: =SUMIFS('Regional allocations LIVE'!$T:$T, 'Regional allocations LIVE'!$H:$H, $R12, 'Regional allocations LIVE'!$R:$R, ">=" & AX$4, 'Regional allocations LIVE'!$R:$R, "<=" & Table14[[#Headers],[30/01/2027]] ) -> 0 | AY12: =SUMIFS('Regional allocations LIVE'!$T:$T, 'Regional allocations LIVE'!$H:$H, $R12, 'Regional allocations LIVE'!$R:$R, ">=" & AY$4, 'Regional allocations LIVE'!$R:$R, "<=" & Table14[[#Headers],[28/02/2027]] ) -> 0 | AZ12: =SUMIFS('Regional allocations LIVE'!$T:$T, 'Regional allocations LIVE'!$H:$H, $R12, 'Regional allocations LIVE'!$R:$R, ">=" & AZ$4, 'Regional allocations LIVE'!$R:$R, "<=" & Table14[[#Headers],[31/03/2027]] ) -> 0 | BA12: =SUMIFS('Regional allocations LIVE'!$T:$T, 'Regional allocations LIVE'!$H:$H, $R12, 'Regional allocations LIVE'!$R:$R, ">=" & BA$4, 'Regional allocations LIVE'!$R:$R, "<=" & Table14[[#Headers],[30/04/2027]] ) -> 0 | BB12: =SUMIFS('Regional allocations LIVE'!$T:$T, 'Regional allocations LIVE'!$H:$H, $R12, 'Regional allocations LIVE'!$R:$R, ">=" & BB$4, 'Regional allocations LIVE'!$R:$R, "<=" & Table14[[#Headers],[31/05/2027]] ) -> 0 | BC12: =SUMIFS('Regional allocations LIVE'!$T:$T, 'Regional allocations LIVE'!$H:$H, $R12, 'Regional allocations LIVE'!$R:$R, ">=" & BC$4, 'Regional allocations LIVE'!$R:$R, "<=" & Table14[[#Headers],[30/06/2027]] ) -> 0 | BD12: =SUMIFS('Regional allocations LIVE'!$T:$T, 'Regional allocations LIVE'!$H:$H, $R12, 'Regional allocations LIVE'!$R:$R, ">=" & BD$4, 'Regional allocations LIVE'!$R:$R, "<=" & Table14[[#Headers],[31/07/2027]] ) -> 0 | BE12: =SUMIFS('Regional allocations LIVE'!$T:$T, 'Regional allocations LIVE'!$H:$H, $R12, 'Regional allocations LIVE'!$R:$R, ">=" & BE$4, 'Regional allocations LIVE'!$R:$R, "<=" & Table14[[#Headers],[31/08/2027]] ) -> 0 | BF12: =SUMIFS('Regional allocations LIVE'!$T:$T, 'Regional allocations LIVE'!$H:$H, $R12, 'Regional allocations LIVE'!$R:$R, ">=" & BF$4, 'Regional allocations LIVE'!$R:$R, "<=" & Table14[[#Headers],[30/09/2027]] ) -> 0 | BG12: =SUMIFS('Regional allocations LIVE'!$T:$T, 'Regional allocations LIVE'!$H:$H, $R12, 'Regional allocations LIVE'!$R:$R, ">=" & BG$4, 'Regional allocations LIVE'!$R:$R, "<=" & Table14[[#Headers],[31/10/2027]] ) -> 0
B13: ELT | C13: =AD45 -> 0 | H13: ELT | I13: =COUNTIFS('Regional allocations LIVE'!H:H,Table1116[[#This Row],[Business Unit]],'Regional allocations LIVE'!R:R,"") -> 0 | J13: 1 | M13: =COUNTIFS('Regional allocations LIVE'!H:H,Table1116[[#This Row],[Business Unit]],'Regional allocations LIVE'!U:U,"Y",'Regional allocations LIVE'!R:R,"") -> 0 | N13: =Table1116[[#This Row],[Headcount]]-Table1116[[#This Row],[Contractors]] -> 0 | O13: =Table1116[[#This Row],[Perm Headcount (minus contractors)]]+Table1116[[#This Row],[Vaccancies to backfill]]+Table1116[[#This Row],[Vaccancies for new roles]] -> 1 | R13: Clever Cloud | S13: 0 | T13: 0 | U13: 0 | V13: 0 | W13: 0 | AF13: =SUMIFS('Regional allocations LIVE'!$T:$T, 'Regional allocations LIVE'!$H:$H, $R13, 'Regional allocations LIVE'!$R:$R, ">=" & AF$4, 'Regional allocations LIVE'!$R:$R, "<=" & Table14[[#Headers],[31/07/2025]] ) -> 0 | AG13: =SUMIFS('Regional allocations LIVE'!$T:$T, 'Regional allocations LIVE'!$H:$H, $R13, 'Regional allocations LIVE'!$R:$R, ">=" & AG$4, 'Regional allocations LIVE'!$R:$R, "<=" & Table14[[#Headers],[31/08/2025]] ) -> 0 | AH13: =SUMIFS('Regional allocations LIVE'!$T:$T, 'Regional allocations LIVE'!$H:$H, $R13, 'Regional allocations LIVE'!$R:$R, ">=" & AH$4, 'Regional allocations LIVE'!$R:$R, "<=" & Table14[[#Headers],[30/09/2025]] ) -> 0 | AI13: =SUMIFS('Regional allocations LIVE'!$T:$T, 'Regional allocations LIVE'!$H:$H, $R13, 'Regional allocations LIVE'!$R:$R, ">=" & AI$4, 'Regional allocations LIVE'!$R:$R, "<=" & Table14[[#Headers],[31/10/2025]] ) -> 0 | AJ13: =SUMIFS('Regional allocations LIVE'!$T:$T, 'Regional allocations LIVE'!$H:$H, $R13, 'Regional allocations LIVE'!$R:$R, ">=" & AJ$4, 'Regional allocations LIVE'!$R:$R, "<=" & Table14[[#Headers],[30/11/2025]] ) -> 0 | AK13: =SUMIFS('Regional allocations LIVE'!$T:$T, 'Regional allocations LIVE'!$H:$H, $R13, 'Regional allocations LIVE'!$R:$R, ">=" & AK$4, 'Regional allocations LIVE'!$R:$R, "<=" & Table14[[#Headers],[31/12/2025]] ) -> 0 | AL13: =SUMIFS('Regional allocations LIVE'!$T:$T, 'Regional allocations LIVE'!$H:$H, $R13, 'Regional allocations LIVE'!$R:$R, ">=" & AL$4, 'Regional allocations LIVE'!$R:$R, "<=" & Table14[[#Headers],[30/01/2026]] ) -> 0 | AM13: =SUMIFS('Regional allocations LIVE'!$T:$T, 'Regional allocations LIVE'!$H:$H, $R13, 'Regional allocations LIVE'!$R:$R, ">=" & AM$4, 'Regional allocations LIVE'!$R:$R, "<=" & Table14[[#Headers],[28/02/2026]] ) -> 0 | AN13: =SUMIFS('Regional allocations LIVE'!$T:$T, 'Regional allocations LIVE'!$H:$H, $R13, 'Regional allocations LIVE'!$R:$R, ">=" & AN$4, 'Regional allocations LIVE'!$R:$R, "<=" & Table14[[#Headers],[31/03/2026]] ) -> 0 | AO13: =SUMIFS('Regional allocations LIVE'!$T:$T, 'Regional allocations LIVE'!$H:$H, $R13, 'Regional allocations LIVE'!$R:$R, ">=" & AO$4, 'Regional allocations LIVE'!$R:$R, "<=" & Table14[[#Headers],[30/04/2026]] ) -> 0 | AP13: =SUMIFS('Regional allocations LIVE'!$T:$T, 'Regional allocations LIVE'!$H:$H, $R13, 'Regional allocations LIVE'!$R:$R, ">=" & AP$4, 'Regional allocations LIVE'!$R:$R, "<=" & Table14[[#Headers],[31/05/2026]] ) -> 0 | AQ13: =SUMIFS('Regional allocations LIVE'!$T:$T, 'Regional allocations LIVE'!$H:$H, $R13, 'Regional allocations LIVE'!$R:$R, ">=" & AQ$4, 'Regional allocations LIVE'!$R:$R, "<=" & Table14[[#Headers],[30/06/2026]] ) -> 0 | AR13: =SUMIFS('Regional allocations LIVE'!$T:$T, 'Regional allocations LIVE'!$H:$H, $R13, 'Regional allocations LIVE'!$R:$R, ">=" & AR$4, 'Regional allocations LIVE'!$R:$R, "<=" & Table14[[#Headers],[31/07/2026]] ) -> 0 | AS13: =SUMIFS('Regional allocations LIVE'!$T:$T, 'Regional allocations LIVE'!$H:$H, $R13, 'Regional allocations LIVE'!$R:$R, ">=" & AS$4, 'Regional allocations LIVE'!$R:$R, "<=" & Table14[[#Headers],[31/08/2026]] ) -> 0 | AT13: =SUMIFS('Regional allocations LIVE'!$T:$T, 'Regional allocations LIVE'!$H:$H, $R13, 'Regional allocations LIVE'!$R:$R, ">=" & AT$4, 'Regional allocations LIVE'!$R:$R, "<=" & Table14[[#Headers],[30/09/2026]] ) -> 0 | AU13: =SUMIFS('Regional allocations LIVE'!$T:$T, 'Regional allocations LIVE'!$H:$H, $R13, 'Regional allocations LIVE'!$R:$R, ">=" & AU$4, 'Regional allocations LIVE'!$R:$R, "<=" & Table14[[#Headers],[31/10/2026]] ) -> 0 | AV13: =SUMIFS('Regional allocations LIVE'!$T:$T, 'Regional allocations LIVE'!$H:$H, $R13, 'Regional allocations LIVE'!$R:$R, ">=" & AV$4, 'Regional allocations LIVE'!$R:$R, "<=" & Table14[[#Headers],[30/11/2026]] ) -> 0 | AW13: =SUMIFS('Regional allocations LIVE'!$T:$T, 'Regional allocations LIVE'!$H:$H, $R13, 'Regional allocations LIVE'!$R:$R, ">=" & AW$4, 'Regional allocations LIVE'!$R:$R, "<=" & Table14[[#Headers],[31/12/2026]] ) -> 0 | AX13: =SUMIFS('Regional allocations LIVE'!$T:$T, 'Regional allocations LIVE'!$H:$H, $R13, 'Regional allocations LIVE'!$R:$R, ">=" & AX$4, 'Regional allocations LIVE'!$R:$R, "<=" & Table14[[#Headers],[30/01/2027]] ) -> 0 | AY13: =SUMIFS('Regional allocations LIVE'!$T:$T, 'Regional allocations LIVE'!$H:$H, $R13, 'Regional allocations LIVE'!$R:$R, ">=" & AY$4, 'Regional allocations LIVE'!$R:$R, "<=" & Table14[[#Headers],[28/02/2027]] ) -> 0 | AZ13: =SUMIFS('Regional allocations LIVE'!$T:$T, 'Regional allocations LIVE'!$H:$H, $R13, 'Regional allocations LIVE'!$R:$R, ">=" & AZ$4, 'Regional allocations LIVE'!$R:$R, "<=" & Table14[[#Headers],[31/03/2027]] ) -> 0 | BA13: =SUMIFS('Regional allocations LIVE'!$T:$T, 'Regional allocations LIVE'!$H:$H, $R13, 'Regional allocations LIVE'!$R:$R, ">=" & BA$4, 'Regional allocations LIVE'!$R:$R, "<=" & Table14[[#Headers],[30/04/2027]] ) -> 0 | BB13: =SUMIFS('Regional allocations LIVE'!$T:$T, 'Regional allocations LIVE'!$H:$H, $R13, 'Regional allocations LIVE'!$R:$R, ">=" & BB$4, 'Regional allocations LIVE'!$R:$R, "<=" & Table14[[#Headers],[31/05/2027]] ) -> 0 | BC13: =SUMIFS('Regional allocations LIVE'!$T:$T, 'Regional allocations LIVE'!$H:$H, $R13, 'Regional allocations LIVE'!$R:$R, ">=" & BC$4, 'Regional allocations LIVE'!$R:$R, "<=" & Table14[[#Headers],[30/06/2027]] ) -> 0 | BD13: =SUMIFS('Regional allocations LIVE'!$T:$T, 'Regional allocations LIVE'!$H:$H, $R13, 'Regional allocations LIVE'!$R:$R, ">=" & BD$4, 'Regional allocations LIVE'!$R:$R, "<=" & Table14[[#Headers],[31/07/2027]] ) -> 0 | BE13: =SUMIFS('Regional allocations LIVE'!$T:$T, 'Regional allocations LIVE'!$H:$H, $R13, 'Regional allocations LIVE'!$R:$R, ">=" & BE$4, 'Regional allocations LIVE'!$R:$R, "<=" & Table14[[#Headers],[31/08/2027]] ) -> 0 | BF13: =SUMIFS('Regional allocations LIVE'!$T:$T, 'Regional allocations LIVE'!$H:$H, $R13, 'Regional allocations LIVE'!$R:$R, ">=" & BF$4, 'Regional allocations LIVE'!$R:$R, "<=" & Table14[[#Headers],[30/09/2027]] ) -> 0 | BG13: =SUMIFS('Regional allocations LIVE'!$T:$T, 'Regional allocations LIVE'!$H:$H, $R13, 'Regional allocations LIVE'!$R:$R, ">=" & BG$4, 'Regional allocations LIVE'!$R:$R, "<=" & Table14[[#Headers],[31/10/2027]] ) -> 0
